<mujoco model="unnamed_model">
  <default>
    <default class="/"/>
  </default>
  <worldbody>
    <geom name="//unnamed_geom_0" class="/" type="plane" size="100 100 0.10000000000000001" pos="0 0 -1.8916027811660161"/>
    <body name="body0" pos="0 0 0">
      <joint name="//unnamed_joint_0" class="/" type="free"/>
      <geom name="//unnamed_geom_1" class="/" type="sphere" size="0.56723617840109775 0.56723617840109775 0.56723617840109775"/>
      <body name="body1" pos="0 -1.2869625928365598 0">
        <geom name="//unnamed_geom_2" class="/" type="sphere" size="0.71972641443546204 0.71972641443546204 0.71972641443546204"/>
        <joint name="//unnamed_joint_1" class="/" type="hinge" axis="0 1 0"/>
        <body name="body2" pos="0 -1.6113291956014781 0">
          <geom name="//unnamed_geom_3" class="/" type="sphere" size="0.8916027811660161 0.8916027811660161 0.8916027811660161"/>
          <joint name="//unnamed_joint_2" class="/" type="hinge" axis="0 1 0"/>
        </body>
      </body>
    </body>
  </worldbody>
  <actuator>
    <motor name="body1_motor" class="/" ctrllimited="true" ctrlrange="-100 100" joint="//unnamed_joint_1"/>
    <motor name="body2_motor" class="/" ctrllimited="true" ctrlrange="-100 100" joint="//unnamed_joint_2"/>
  </actuator>
</mujoco>
