<mujoco model="unnamed_model">
  <default>
    <default class="/"/>
  </default>
  <worldbody>
    <geom name="//unnamed_geom_0" class="/" type="plane" size="100 100 0.10000000000000001" pos="0 0 -5.2695291766802219"/>
    <body name="body0" pos="0 0 0">
      <joint name="//unnamed_joint_0" class="/" type="free"/>
      <geom name="//unnamed_geom_1" class="/" type="sphere" size="0.56415140211447212 0.56415140211447212 0.56415140211447212"/>
      <body name="body1" pos="0 -1.4473703433252521 0">
        <geom name="//unnamed_geom_2" class="/" type="sphere" size="0.88321894121077982 0.88321894121077982 0.88321894121077982"/>
        <joint name="//unnamed_joint_1" class="/" type="hinge" axis="0 1 0"/>
        <body name="body2" pos="0 0 -1.7175827059636672">
          <geom name="//unnamed_geom_3" class="/" type="sphere" size="0.83436376475288743 0.83436376475288743 0.83436376475288743"/>
          <joint name="//unnamed_joint_2" class="/" type="hinge" axis="0 0 1"/>
          <body name="body3" pos="0 -1.627251237210058 0">
            <geom name="//unnamed_geom_4" class="/" type="sphere" size="0.79288747245717062 0.79288747245717062 0.79288747245717062"/>
            <joint name="//unnamed_joint_3" class="/" type="hinge" axis="0 1 0"/>
            <body name="body4" pos="0 -1.5483960404033998 0">
              <geom name="//unnamed_geom_5" class="/" type="sphere" size="0.75550856794622923 0.75550856794622923 0.75550856794622923"/>
              <joint name="//unnamed_joint_4" class="/" type="hinge" axis="0 1 0"/>
            </body>
          </body>
        </body>
      </body>
    </body>
  </worldbody>
  <actuator>
    <motor name="body1_motor" class="/" ctrllimited="true" ctrlrange="-100 100" joint="//unnamed_joint_1"/>
    <motor name="body2_motor" class="/" ctrllimited="true" ctrlrange="-100 100" joint="//unnamed_joint_2"/>
    <motor name="body3_motor" class="/" ctrllimited="true" ctrlrange="-100 100" joint="//unnamed_joint_3"/>
    <motor name="body4_motor" class="/" ctrllimited="true" ctrlrange="-100 100" joint="//unnamed_joint_4"/>
  </actuator>
</mujoco>
