<mujoco model="unnamed_model">
  <default>
    <default class="/"/>
  </default>
  <worldbody>
    <geom name="//unnamed_geom_0" class="/" type="plane" size="100 100 0.10000000000000001" pos="0 0 -7.2947228637463208"/>
    <body name="body0" pos="0 0 0">
      <joint name="//unnamed_joint_0" class="/" type="free"/>
      <geom name="//unnamed_geom_1" class="/" type="sphere" size="0.83540273454038494 0.83540273454038494 0.83540273454038494"/>
      <body name="body1" pos="0 0 -1.8151006953633786">
        <geom name="//unnamed_geom_2" class="/" type="sphere" size="0.97969796082299365 0.97969796082299365 0.97969796082299365"/>
        <joint name="//unnamed_joint_1" class="/" type="hinge" axis="0 0 1"/>
        <body name="body2" pos="0 0 -1.8197733764019786">
          <geom name="//unnamed_geom_3" class="/" type="sphere" size="0.84007541557898491 0.84007541557898491 0.84007541557898491"/>
          <joint name="//unnamed_joint_2" class="/" type="hinge" axis="0 0 1"/>
          <body name="body3" pos="1.3721442702935398 0 0">
            <geom name="//unnamed_geom_4" class="/" type="sphere" size="0.5320688547145549 0.5320688547145549 0.5320688547145549"/>
            <joint name="//unnamed_joint_3" class="/" type="ball" axis="-1 0 0"/>
          </body>
        </body>
      </body>
    </body>
  </worldbody>
  <actuator>
    <motor name="body1_motor" class="/" ctrllimited="true" ctrlrange="-100 100" joint="//unnamed_joint_1"/>
    <motor name="body2_motor" class="/" ctrllimited="true" ctrlrange="-100 100" joint="//unnamed_joint_2"/>
    <motor name="body3_motor" class="/" ctrllimited="true" ctrlrange="-100 100" joint="//unnamed_joint_3"/>
  </actuator>
</mujoco>
